2021-02-12T03:31:08.490779+00:00 heroku[web.1]: Starting process with command `gunicorn argo.wsgi --log-file -`
2021-02-12T03:31:11.128992+00:00 app[web.1]: [2021-02-12 03:31:11 +0000] [4] [INFO] Starting gunicorn 20.0.4
2021-02-12T03:31:11.129661+00:00 app[web.1]: [2021-02-12 03:31:11 +0000] [4] [INFO] Listening at: http://0.0.0.0:41307 (4)
2021-02-12T03:31:11.129831+00:00 app[web.1]: [2021-02-12 03:31:11 +0000] [4] [INFO] Using worker: sync
2021-02-12T03:31:11.135831+00:00 app[web.1]: [2021-02-12 03:31:11 +0000] [7] [INFO] Booting worker with pid: 7
2021-02-12T03:31:11.180611+00:00 app[web.1]: [2021-02-12 03:31:11 +0000] [8] [INFO] Booting worker with pid: 8
2021-02-12T03:31:11.249008+00:00 heroku[web.1]: State changed from starting to up
2021-02-12T03:31:13.000000+00:00 app[api]: Build succeeded
2021-02-12T03:33:51.431445+00:00 heroku[router]: at=info method=GET path="/robots.txt" host=argooo.herokuapp.com request_id=4a365341-1dbc-41dc-91ed-e7d8810b0361 fwd="154.13.1.235" dyno=web.1 connect=1ms service=261ms status=404 bytes=5977 protocol=http
2021-02-12T03:33:51.430136+00:00 app[web.1]: Not Found: /robots.txt
2021-02-12T03:33:51.431111+00:00 app[web.1]: 10.67.225.150 - - [12/Feb/2021:03:33:51 +0000] "GET /robots.txt HTTP/1.1" 404 5737 "-" "Mozilla/5.0 (X11; Linux x86_64) AppleWebKit/537.36 (KHTML, like Gecko) Chrome/84.0.4147.125 Safari/537.36"
2021-02-12T03:33:51.787800+00:00 app[web.1]: 10.45.78.78 - - [12/Feb/2021:03:33:51 +0000] "GET /plans HTTP/1.1" 301 0 "-" "Mozilla/5.0 (X11; Linux x86_64) AppleWebKit/537.36 (KHTML, like Gecko) Chrome/84.0.4147.125 Safari/537.36"
2021-02-12T03:33:51.787136+00:00 heroku[router]: at=info method=GET path="/plans" host=argooo.herokuapp.com request_id=2e4c6e96-6701-4c94-bf69-f1646e08875d fwd="154.13.1.235" dyno=web.1 connect=1ms service=4ms status=301 bytes=256 protocol=https
2021-02-12T03:33:52.519436+00:00 app[web.1]: Internal Server Error: /plans/
2021-02-12T03:33:52.519466+00:00 app[web.1]: Traceback (most recent call last):
2021-02-12T03:33:52.519484+00:00 app[web.1]:   File "/app/.heroku/python/lib/python3.9/site-packages/django/db/backends/utils.py", line 84, in _execute
2021-02-12T03:33:52.519485+00:00 app[web.1]:     return self.cursor.execute(sql, params)
2021-02-12T03:33:52.519486+00:00 app[web.1]: psycopg2.errors.UndefinedColumn: column frontend_plansplan.price_in_dollor does not exist
2021-02-12T03:33:52.519486+00:00 app[web.1]: LINE 1: ...nd_plansplan"."id", "frontend_plansplan"."price", "frontend_...
2021-02-12T03:33:52.519487+00:00 app[web.1]:                                                              ^
2021-02-12T03:33:52.519488+00:00 app[web.1]: 
2021-02-12T03:33:52.519488+00:00 app[web.1]: 
2021-02-12T03:33:52.519489+00:00 app[web.1]: The above exception was the direct cause of the following exception:
2021-02-12T03:33:52.519489+00:00 app[web.1]: 
2021-02-12T03:33:52.519490+00:00 app[web.1]: Traceback (most recent call last):
2021-02-12T03:33:52.519490+00:00 app[web.1]:   File "/app/.heroku/python/lib/python3.9/site-packages/django/core/handlers/exception.py", line 47, in inner
2021-02-12T03:33:52.519491+00:00 app[web.1]:     response = get_response(request)
2021-02-12T03:33:52.519491+00:00 app[web.1]:   File "/app/.heroku/python/lib/python3.9/site-packages/django/core/handlers/base.py", line 181, in _get_response
2021-02-12T03:33:52.519492+00:00 app[web.1]:     response = wrapped_callback(request, *callback_args, **callback_kwargs)
2021-02-12T03:33:52.519492+00:00 app[web.1]:   File "/app/.heroku/python/lib/python3.9/site-packages/django/contrib/auth/decorators.py", line 21, in _wrapped_view
2021-02-12T03:33:52.519493+00:00 app[web.1]:     return view_func(request, *args, **kwargs)
2021-02-12T03:33:52.519494+00:00 app[web.1]:   File "/app/frontend/views.py", line 317, in plans
2021-02-12T03:33:52.519494+00:00 app[web.1]:     for plan in PlansPlan.objects.all():
2021-02-12T03:33:52.519494+00:00 app[web.1]:   File "/app/.heroku/python/lib/python3.9/site-packages/django/db/models/query.py", line 287, in __iter__
2021-02-12T03:33:52.519495+00:00 app[web.1]     self._fetch_all()
2021-02-12T03:33:52.519495+00:00 app[web.1]:   File "/app/.heroku/python/lib/python3.9/site-packages/django/db/models/query.py", line 1308, in _fetch_all
2021-02-12T03:33:52.519496+00:00 app[web.1]:     self._result_cache = list(self._iterable_class(self))
2021-02-12T03:33:52.519496+00:00 app[web.1]:   File "/app/.heroku/python/lib/python3.9/site-packages/django/db/models/query.py", line 53, in __iter__
2021-02-12T03:33:52.519497+00:00 app[web.1]:     results = compiler.execute_sql(chunked_fetch=self.chunked_fetch, chunk_size=self.chunk_size)
2021-02-12T03:33:52.519497+00:00 app[web.1]:   File "/app/.heroku/python/lib/python3.9/site-packages/django/db/models/sql/compiler.py", line 1156, in execute_sql
2021-02-12T03:33:52.519498+00:00 app[web.1]:     cursor.execute(sql, params)
2021-02-12T03:33:52.519498+00:00 app[web.1]:   File "/app/.heroku/python/lib/python3.9/site-packages/django/db/backends/utils.py", line 98, in execute
2021-02-12T03:33:52.519498+00:00 app[web.1]:     return super().execute(sql, params)
2021-02-12T03:33:52.519499+00:00 app[web.1]:   File "/app/.heroku/python/lib/python3.9/site-packages/django/db/backends/utils.py", line 66, in execute
2021-02-12T03:33:52.519499+00:00 app[web.1]:     return self._execute_with_wrappers(sql, params, many=False, executor=self._execute)
2021-02-12T03:33:52.519500+00:00 app[web.1]:   File "/app/.heroku/python/lib/python3.9/site-packages/django/db/backends/utils.py", line 75, in _execute_with_wrappers
2021-02-12T03:33:52.519500+00:00 app[web.1]:     return executor(sql, params, many, context)
2021-02-12T03:33:52.519501+00:00 app[web.1]:   File "/app/.heroku/python/lib/python3.9/site-packages/django/db/backends/utils.py", line 84, in _execute
2021-02-12T03:33:52.519501+00:00 app[web.1]:     return self.cursor.execute(sql, params)
2021-02-12T03:33:52.519501+00:00 app[web.1]:   File "/app/.heroku/python/lib/python3.9/site-packages/django/db/utils.py", line 90, in __exit__
2021-02-12T03:33:52.519502+00:00 app[web.1]:     raise dj_exc_value.with_traceback(traceback) from exc_value
2021-02-12T03:33:52.519502+00:00 app[web.1]:   File "/app/.heroku/python/lib/python3.9/site-packages/django/db/backends/utils.py", line 84, in _execute
2021-02-12T03:33:52.519503+00:00 app[web.1]:     return self.cursor.execute(sql, params)
2021-02-12T03:33:52.519503+00:00 app[web.1]: django.db.utils.ProgrammingError: column frontend_plansplan.price_in_dollor does not exist
2021-02-12T03:33:52.519504+00:00 app[web.1]: LINE 1: ...nd_plansplan"."id", "frontend_plansplan"."price", "frontend_...
2021-02-12T03:33:52.519504+00:00 app[web.1]:                                                              ^
2021-02-12T03:33:52.519504+00:00 app[web.1]: 
2021-02-12T03:33:52.520995+00:00 app[web.1]: 10.45.78.78 - - [12/Feb/2021:03:33:52 +0000] "GET /plans/ HTTP/1.1" 500 124689 "-" "Mozilla/5.0 (X11; Linux x86_64) AppleWebKit/537.36 (KHTML, like Gecko) Chrome/84.0.4147.125 Safari/537.36"
2021-02-12T03:33:52.525688+00:00 heroku[router]: at=info method=GET path="/plans/" host=argooo.herokuapp.com request_id=15209788-9df2-4f26-a3e3-93b70e4bfd7e fwd="154.13.1.235" dyno=web.1 connect=1ms service=388ms status=500 bytes=124957 protocol=https
2021-02-12T03:33:53.813589+00:00 heroku[router]: at=info method=GET path="/favicon.ico" host=argooo.herokuapp.com request_id=3286f727-2861-4cb2-bcef-0556df8d695c fwd="154.13.1.235" dyno=web.1 connect=1ms service=4ms status=302 bytes=283 protocol=https
2021-02-12T03:33:53.813821+00:00 app[web.1]: 10.45.78.78 - - [12/Feb/2021:03:33:53 +0000] "GET /favicon.ico HTTP/1.1" 302 0 "https://argooo.herokuapp.com/plans/" "Mozilla/5.0 (X11; Linux x86_64) AppleWebKit/537.36 (KHTML, like Gecko) Chrome/84.0.4147.125 Safari/537.36"
2021-02-12T03:33:54.048083+00:00 app[web.1]: 10.45.78.78 - - [12/Feb/2021:03:33:54 +0000] "GET /static/img/favicon.ico HTTP/1.1" 200 0 "https://argooo.herokuapp.com/plans/" "Mozilla/5.0 (X11; Linux x86_64) AppleWebKit/537.36 (KHTML, like Gecko) Chrome/84.0.4147.125 Safari/537.36"
2021-02-12T03:33:54.049482+00:00 heroku[router]: at=info method=GET path="/static/img/favicon.ico" host=argooo.herokuapp.com request_id=d643ca14-b4f6-4df8-a74f-ed49ae674d7b fwd="154.13.1.235" dyno=web.1 connect=1ms service=6ms status=200 bytes=46988 protocol=https:





      No migrations to apply.
Traceback (most recent call last):
  File "/app/.heroku/python/lib/python3.9/site-packages/django/db/models/fields/__init__.py", line 1774, in get_prep_value
    return int(value)
TypeError: int() argument must be a string, a bytes-like object or a number, not 'tuple'

The above exception was the direct cause of the following exception:

Traceback (most recent call last):
  File "/app/manage.py", line 22, in <module>
    main()
  File "/app/manage.py", line 18, in main
    execute_from_command_line(sys.argv)
  File "/app/.heroku/python/lib/python3.9/site-packages/django/core/management/__init__.py", line 401, in execute_from_command_line
    utility.execute()
  File "/app/.heroku/python/lib/python3.9/site-packages/django/core/management/__init__.py", line 395, in execute
    self.fetch_command(subcommand).run_from_argv(self.argv)
  File "/app/.heroku/python/lib/python3.9/site-packages/django/core/management/base.py", line 330, in run_from_argv
    self.execute(*args, **cmd_options)
  File "/app/.heroku/python/lib/python3.9/site-packages/django/core/management/base.py", line 371, in execute
    output = self.handle(*args, **options)
  File "/app/.heroku/python/lib/python3.9/site-packages/django/core/management/base.py", line 85, in wrapped
    res = handle_func(*args, **kwargs)
  File "/app/.heroku/python/lib/python3.9/site-packages/django/core/management/commands/migrate.py", line 267, in handle
    emit_post_migrate_signal(
  File "/app/.heroku/python/lib/python3.9/site-packages/django/core/management/sql.py", line 48, in emit_post_migrate_signal
    models.signals.post_migrate.send(
  File "/app/.heroku/python/lib/python3.9/site-packages/django/dispatch/dispatcher.py", line 177, in send
    return [
  File "/app/.heroku/python/lib/python3.9/site-packages/django/dispatch/dispatcher.py", line 178, in <listcomp>
    (receiver, receiver(signal=self, sender=sender, **named))
  File "/app/.heroku/python/lib/python3.9/site-packages/django/contrib/sites/management.py", line 28, in create_default_site
    Site(pk=getattr(settings, 'SITE_ID', 1), domain="example.com", name="example.com").save(using=using)
  File "/app/.heroku/python/lib/python3.9/site-packages/django/db/models/base.py", line 753, in save
    self.save_base(using=using, force_insert=force_insert,
  File "/app/.heroku/python/lib/python3.9/site-packages/django/db/models/base.py", line 790, in save_base
    updated = self._save_table(
  File "/app/.heroku/python/lib/python3.9/site-packages/django/db/models/base.py", line 872, in _save_table
    updated = self._do_update(base_qs, using, pk_val, values, update_fields,
  File "/app/.heroku/python/lib/python3.9/site-packages/django/db/models/base.py", line 906, in _do_update
    filtered = base_qs.filter(pk=pk_val)
  File "/app/.heroku/python/lib/python3.9/site-packages/django/db/models/query.py", line 942, in filter
    return self._filter_or_exclude(False, *args, **kwargs)
  File "/app/.heroku/python/lib/python3.9/site-packages/django/db/models/query.py", line 962, in _filter_or_exclude
    clone._filter_or_exclude_inplace(negate, *args, **kwargs)
  File "/app/.heroku/python/lib/python3.9/site-packages/django/db/models/query.py", line 969, in _filter_or_exclude_inplace
    self._query.add_q(Q(*args, **kwargs))
  File "/app/.heroku/python/lib/python3.9/site-packages/django/db/models/sql/query.py", line 1358, in add_q
    clause, _ = self._add_q(q_object, self.used_aliases)
  File "/app/.heroku/python/lib/python3.9/site-packages/django/db/models/sql/query.py", line 1377, in _add_q
    child_clause, needed_inner = self.build_filter(
  File "/app/.heroku/python/lib/python3.9/site-packages/django/db/models/sql/query.py", line 1319, in build_filter
    condition = self.build_lookup(lookups, col, value)
  File "/app/.heroku/python/lib/python3.9/site-packages/django/db/models/sql/query.py", line 1165, in build_lookup
    lookup = lookup_class(lhs, rhs)
  File "/app/.heroku/python/lib/python3.9/site-packages/django/db/models/lookups.py", line 24, in __init__
    self.rhs = self.get_prep_lookup)
  File "/app/.heroku/python/lib/python3.9/site-packages/django/db/models/lookups.py", line 76, in get_prep_lookup
    return self.lhs.output_field.get_prep_value(self.rhs)
  File "/app/.heroku/python/lib/python3.9/site-packages/django/db/models/fields/__init__.py", line 1776, in get_prep_value
    raise e.__class__(
TypeError: Field 'id' expected a number but got (1,).(
